<?xml version="1.0"?>
<robot name="four_finger_gripper">

  <!-- Base link (cylindrical end effector) -->
  <link name="base_link">
    <visual>
      <origin xyz="0 0 0" rpy="0 0 0"/>
      <geometry>
        <cylinder radius="0.04" length="0.05"/>
      </geometry>
      <material name="gray">
        <color rgba="0.5 0.5 0.5 1"/>
      </material>
    </visual>
    <collision>
      <origin xyz="0 0 0" rpy="0 0 0"/>
      <geometry>
        <cylinder radius="0.04" length="0.05"/>
      </geometry>
    </collision>
    <inertial>
      <origin xyz="0 0 0" rpy="0 0 0"/>
      <mass value="0.5"/>
      <inertia ixx="0.001" ixy="0" ixz="0" iyy="0.001" iyz="0" izz="0.001"/>
    </inertial>
  </link>

  <!-- Palm link (gripper mounting plate at bottom of cylinder) -->
  <link name="palm_link">
    <visual>
      <origin xyz="0 0 -0.005" rpy="0 0 0"/>
      <geometry>
        <cylinder radius="0.04" length="0.01"/>
      </geometry>
      <material name="dark_gray">
        <color rgba="0.3 0.3 0.3 1"/>
      </material>
    </visual>
    <collision>
      <origin xyz="0 0 -0.005" rpy="0 0 0"/>
      <geometry>
        <cylinder radius="0.04" length="0.01"/>
      </geometry>
    </collision>
    <inertial>
      <origin xyz="0 0 -0.005" rpy="0 0 0"/>
      <mass value="0.2"/>
      <inertia ixx="0.0001" ixy="0" ixz="0" iyy="0.0001" iyz="0" izz="0.0001"/>
    </inertial>
  </link>

  <!-- Fixed joint connecting palm to base -->
  <joint name="base_to_palm" type="fixed">
    <parent link="base_link"/>
    <child link="palm_link"/>
    <origin xyz="0 0 -0.025" rpy="0 0 0"/>
  </joint>

  <!-- Finger 1 (0 degrees - positive X direction) - MASTER JOINT -->
  <link name="finger1_link">
    <visual>
      <origin xyz="0 0 -0.005" rpy="0 0 0"/>
      <geometry>
        <box size="0.003 0.003 0.01"/>
      </geometry>
      <material name="blue">
        <color rgba="0.2 0.4 0.8 1"/>
      </material>
    </visual>
    <collision>
      <origin xyz="0 0 -0.005" rpy="0 0 0"/>
      <geometry>
        <box size="0.003 0.003 0.01"/>
      </geometry>
    </collision>
    <inertial>
      <origin xyz="0 0 -0.005" rpy="0 0 0"/>
      <mass value="0.01"/>
      <inertia ixx="0.000001" ixy="0" ixz="0" iyy="0.000001" iyz="0" izz="0.000001"/>
    </inertial>
  </link>

  <joint name="finger1_joint" type="prismatic">
    <parent link="palm_link"/>
    <child link="finger1_link"/>
    <origin xyz="0.0015 0 -0.01" rpy="0 0 0"/>
    <axis xyz="1 0 0"/>
    <limit lower="0" upper="0.03" effort="100" velocity="0.1"/>
    <dynamics damping="0.1" friction="0.1"/>
  </joint>

  <!-- Finger 2 (90 degrees - positive Y direction) -->
  <link name="finger2_link">
    <visual>
      <origin xyz="0 0 -0.005" rpy="0 0 0"/>
      <geometry>
        <box size="0.003 0.003 0.01"/>
      </geometry>
      <material name="blue">
        <color rgba="0.2 0.4 0.8 1"/>
      </material>
    </visual>
    <collision>
      <origin xyz="0 0 -0.005" rpy="0 0 0"/>
      <geometry>
        <box size="0.003 0.003 0.01"/>
      </geometry>
    </collision>
    <inertial>
      <origin xyz="0 0 -0.005" rpy="0 0 0"/>
      <mass value="0.01"/>
      <inertia ixx="0.000001" ixy="0" ixz="0" iyy="0.000001" iyz="0" izz="0.000001"/>
    </inertial>
  </link>

  <joint name="finger2_joint" type="prismatic">
    <parent link="palm_link"/>
    <child link="finger2_link"/>
    <origin xyz="0 0.0015 -0.01" rpy="0 0 0"/>
    <axis xyz="0 1 0"/>
    <limit lower="0" upper="0.03" effort="100" velocity="0.1"/>
    <dynamics damping="0.1" friction="0.1"/>
    <mimic joint="finger1_joint" multiplier="1" offset="0"/>
  </joint>

  <!-- Finger 3 (180 degrees - negative X direction) -->
  <link name="finger3_link">
    <visual>
      <origin xyz="0 0 -0.005" rpy="0 0 0"/>
      <geometry>
        <box size="0.003 0.003 0.01"/>
      </geometry>
      <material name="blue">
        <color rgba="0.2 0.4 0.8 1"/>
      </material>
    </visual>
    <collision>
      <origin xyz="0 0 -0.005" rpy="0 0 0"/>
      <geometry>
        <box size="0.003 0.003 0.01"/>
      </geometry>
    </collision>
    <inertial>
      <origin xyz="0 0 -0.005" rpy="0 0 0"/>
      <mass value="0.01"/>
      <inertia ixx="0.000001" ixy="0" ixz="0" iyy="0.000001" iyz="0" izz="0.000001"/>
    </inertial>
  </link>

  <joint name="finger3_joint" type="prismatic">
    <parent link="palm_link"/>
    <child link="finger3_link"/>
    <origin xyz="-0.0015 0 -0.01" rpy="0 0 0"/>
    <axis xyz="-1 0 0"/>
    <limit lower="0" upper="0.03" effort="100" velocity="0.1"/>
    <dynamics damping="0.1" friction="0.1"/>
    <mimic joint="finger1_joint" multiplier="1" offset="0"/>
  </joint>

  <!-- Finger 4 (270 degrees - negative Y direction) -->
  <link name="finger4_link">
    <visual>
      <origin xyz="0 0 -0.005" rpy="0 0 0"/>
      <geometry>
        <box size="0.003 0.003 0.01"/>
      </geometry>
      <material name="blue">
        <color rgba="0.2 0.4 0.8 1"/>
      </material>
    </visual>
    <collision>
      <origin xyz="0 0 -0.005" rpy="0 0 0"/>
      <geometry>
        <box size="0.003 0.003 0.01"/>
      </geometry>
    </collision>
    <inertial>
      <origin xyz="0 0 -0.005" rpy="0 0 0"/>
      <mass value="0.01"/>
      <inertia ixx="0.000001" ixy="0" ixz="0" iyy="0.000001" iyz="0" izz="0.000001"/>
    </inertial>
  </link>

  <joint name="finger4_joint" type="prismatic">
    <parent link="palm_link"/>
    <child link="finger4_link"/>
    <origin xyz="0 -0.0015 -0.01" rpy="0 0 0"/>
    <axis xyz="0 -1 0"/>
    <limit lower="0" upper="0.03" effort="100" velocity="0.1"/>
    <dynamics damping="0.1" friction="0.1"/>
    <mimic joint="finger1_joint" multiplier="1" offset="0"/>
  </joint>

</robot>